-- 05/09/19 20:55:08.754 server/server.py: Network: attempting to bind to tcp socket :::10000
-- 05/09/19 20:55:08.760 server/server.py: Network: listening for tcp connections
   local address = :::10000
   local interfaces = 192.168.43.15, ::1, 127.0.0.1
-- 05/09/19 20:55:08.764 server/server.py: Network: published endpoints for object adapter `SimpleManagerAdapter':
   tcp -h 192.168.43.15 -p 10000 -t 60000
-- 05/09/19 20:55:08.765 server/server.py: Network: accepting tcp connections at :::10000
-- 05/09/19 21:05:50.035 server/server.py: Network: stopping to accept tcp connections at :::10000
-- 05/09/19 21:06:06.158 server/server.py: Network: attempting to bind to tcp socket :::10000
-- 05/09/19 21:06:06.164 server/server.py: Network: listening for tcp connections
   local address = :::10000
   local interfaces = 192.168.43.15, ::1, 127.0.0.1
-- 05/09/19 21:06:06.167 server/server.py: Network: published endpoints for object adapter `SimpleManagerAdapter':
   tcp -h 192.168.43.15 -p 10000 -t 60000
-- 05/09/19 21:06:06.168 server/server.py: Network: accepting tcp connections at :::10000
-- 05/09/19 21:07:42.178 server/server.py: Network: trying to accept tcp connection
   local address = ::ffff:192.168.43.15:10000
   remote address = ::ffff:192.168.43.15:61824
-- 05/09/19 21:07:42.178 server/server.py: Network: accepted tcp connection
   local address = ::ffff:192.168.43.15:10000
   remote address = ::ffff:192.168.43.15:61824
-- 05/09/19 21:08:50.730 server/server.py: Network: stopping to accept tcp connections at :::10000
-- 05/09/19 21:08:50.736 server/server.py: Network: closed tcp connection
   local address = ::ffff:192.168.43.15:10000
   remote address = ::ffff:192.168.43.15:61824
-- 05/09/19 21:09:15.475 server/server.py: Network: attempting to bind to tcp socket :::10000
-- 05/09/19 21:09:15.480 server/server.py: Network: listening for tcp connections
   local address = :::10000
   local interfaces = 192.168.43.15, ::1, 127.0.0.1
-- 05/09/19 21:09:15.484 server/server.py: Network: published endpoints for object adapter `SimpleManagerAdapter':
   tcp -h 192.168.43.15 -p 10000 -t 60000
-- 05/09/19 21:09:15.484 server/server.py: Network: accepting tcp connections at :::10000
-- 05/09/19 21:09:16.474 server/server.py: Network: trying to accept tcp connection
   local address = ::ffff:192.168.43.15:10000
   remote address = ::ffff:192.168.43.15:61887
-- 05/09/19 21:09:16.474 server/server.py: Network: accepted tcp connection
   local address = ::ffff:192.168.43.15:10000
   remote address = ::ffff:192.168.43.15:61887
-- 05/09/19 21:09:29.998 server/server.py: Network: stopping to accept tcp connections at :::10000
-- 05/09/19 21:09:30.003 server/server.py: Network: closed tcp connection
   local address = ::ffff:192.168.43.15:10000
   remote address = ::ffff:192.168.43.15:61887
-- 05/09/19 21:14:53.391 server/server.py: Network: attempting to bind to tcp socket :::10000
-- 05/09/19 21:14:53.397 server/server.py: Network: listening for tcp connections
   local address = :::10000
   local interfaces = 192.168.43.15, ::1, 127.0.0.1
-- 05/09/19 21:14:53.402 server/server.py: Network: published endpoints for object adapter `SimpleManagerAdapter':
   tcp -h 192.168.43.15 -p 10000 -t 60000
-- 05/09/19 21:14:53.402 server/server.py: Network: accepting tcp connections at :::10000
-- 05/09/19 21:15:51.903 server/server.py: Network: trying to accept tcp connection
   local address = ::ffff:192.168.43.15:10000
   remote address = ::ffff:192.168.43.1:46542
-- 05/09/19 21:15:51.903 server/server.py: Network: accepted tcp connection
   local address = ::ffff:192.168.43.15:10000
   remote address = ::ffff:192.168.43.1:46542
-- 05/09/19 21:15:53.001 server/server.py: Network: closed tcp connection
   local address = ::ffff:192.168.43.15:10000
   remote address = ::ffff:192.168.43.1:46542
-- 05/09/19 21:16:15.447 server/server.py: Network: trying to accept tcp connection
   local address = ::ffff:192.168.43.15:10000
   remote address = ::ffff:192.168.43.15:62154
-- 05/09/19 21:16:15.447 server/server.py: Network: accepted tcp connection
   local address = ::ffff:192.168.43.15:10000
   remote address = ::ffff:192.168.43.15:62154
-! 05/09/19 21:16:35.349 server/server.py: warning: connection exception:
   src\ice\cpp\src\Ice\StreamSocket.cpp:474: ::Ice::ConnectionLostException:
   connection lost: Le nom réseau spécifié n’est plus disponible.
   local address = ::ffff:192.168.43.15:10000
   remote address = ::ffff:192.168.43.15:62154
-- 05/09/19 21:16:35.350 server/server.py: Network: closed tcp connection
   local address = ::ffff:192.168.43.15:10000
   remote address = ::ffff:192.168.43.15:62154
   src\ice\cpp\src\Ice\StreamSocket.cpp:474: ::Ice::ConnectionLostException:
   connection lost: Le nom réseau spécifié n’est plus disponible.
-- 05/09/19 21:17:53.988 server/server.py: Network: trying to accept tcp connection
   local address = ::ffff:192.168.43.15:10000
   remote address = ::ffff:192.168.43.1:46550
-- 05/09/19 21:17:53.989 server/server.py: Network: accepted tcp connection
   local address = ::ffff:192.168.43.15:10000
   remote address = ::ffff:192.168.43.1:46550
-- 05/09/19 21:17:54.323 server/server.py: Network: closed tcp connection
   local address = ::ffff:192.168.43.15:10000
   remote address = ::ffff:192.168.43.1:46550
-- 05/09/19 21:19:18.252 server/server.py: Network: trying to accept tcp connection
   local address = ::ffff:192.168.43.15:10000
   remote address = ::ffff:192.168.43.1:46558
-- 05/09/19 21:19:18.252 server/server.py: Network: accepted tcp connection
   local address = ::ffff:192.168.43.15:10000
   remote address = ::ffff:192.168.43.1:46558
-- 05/09/19 21:19:18.534 server/server.py: Network: closed tcp connection
   local address = ::ffff:192.168.43.15:10000
   remote address = ::ffff:192.168.43.1:46558
-- 05/09/19 21:26:25.456 server/server.py: Network: stopping to accept tcp connections at :::10000
-- 05/09/19 21:26:34.004 server/server.py: Network: attempting to bind to tcp socket :::10000
-- 05/09/19 21:26:34.010 server/server.py: Network: listening for tcp connections
   local address = :::10000
   local interfaces = 192.168.43.15, ::1, 127.0.0.1
-- 05/09/19 21:26:34.015 server/server.py: Network: published endpoints for object adapter `SimpleManagerAdapter':
   tcp -h 192.168.43.15 -p 10000 -t 60000
-- 05/09/19 21:26:34.015 server/server.py: Network: accepting tcp connections at :::10000
-- 05/09/19 21:26:48.370 server/server.py: Network: trying to accept tcp connection
   local address = ::ffff:192.168.43.15:10000
   remote address = ::ffff:192.168.43.1:46573
-- 05/09/19 21:26:48.370 server/server.py: Network: accepted tcp connection
   local address = ::ffff:192.168.43.15:10000
   remote address = ::ffff:192.168.43.1:46573
-- 05/09/19 21:26:49.276 server/server.py: Network: closed tcp connection
   local address = ::ffff:192.168.43.15:10000
   remote address = ::ffff:192.168.43.1:46573
-- 05/09/19 21:28:23.149 server/server.py: Network: stopping to accept tcp connections at :::10000
-- 05/09/19 21:28:28.919 server/server.py: Network: attempting to bind to tcp socket :::10000
-- 05/09/19 21:28:28.923 server/server.py: Network: listening for tcp connections
   local address = :::10000
   local interfaces = 192.168.43.15, ::1, 127.0.0.1
-- 05/09/19 21:28:28.927 server/server.py: Network: published endpoints for object adapter `SimpleManagerAdapter':
   tcp -h 192.168.43.15 -p 10000 -t 60000
-- 05/09/19 21:28:28.927 server/server.py: Network: accepting tcp connections at :::10000
-- 05/09/19 21:56:47.898 server/server.py: Network: trying to accept tcp connection
   local address = ::ffff:192.168.43.15:10000
   remote address = ::ffff:192.168.43.1:46612
-- 05/09/19 21:56:47.899 server/server.py: Network: accepted tcp connection
   local address = ::ffff:192.168.43.15:10000
   remote address = ::ffff:192.168.43.1:46612
-! 05/09/19 21:56:59.088 server/server.py: warning: dispatch exception: src\Util.cpp:344: ::Ice::UnknownException:
   unknown exception:
   Traceback (most recent call last):
     File "C:\Program Files\Python37\lib\site-packages\pymongo\pool.py", line 1038, in _get_socket_no_auth
       sock_info = self.sockets.pop()
   KeyError: 'pop from an empty set'
   
   During handling of the above exception, another exception occurred:
   
   Traceback (most recent call last):
     File "C:\Program Files\Python37\lib\site-packages\pymongo\pool.py", line 968, in connect
       sock = _configured_socket(self.address, self.opts)
     File "C:\Program Files\Python37\lib\site-packages\pymongo\pool.py", line 843, in _configured_socket
       sock = _create_connection(address, options)
     File "C:\Program Files\Python37\lib\site-packages\pymongo\pool.py", line 796, in _create_connection
       for res in socket.getaddrinfo(host, port, family, socket.SOCK_STREAM):
     File "C:\Program Files\Python37\lib\socket.py", line 748, in getaddrinfo
       for res in _socket.getaddrinfo(host, port, family, type, proto, flags):
   socket.gaierror: [Errno 11001] getaddrinfo failed
   
   During handling of the above exception, another exception occurred:
   
   Traceback (most recent call last):
     File "C:\Program Files\Python37\lib\site-packages\Ice\__init__.py", line 408, in _iceDispatch
       result = method(*args)
     File "server/server.py", line 88, in rechercherParTitre
       queryCount = self.collecMusique.count_documents({"titre": title}, collation = Collation(locale = 'fr', strength = 2))
     File "C:\Program Files\Python37\lib\site-packages\pymongo\collection.py", line 1683, in count_documents
       with self._socket_for_reads(session) as (sock_info, slave_ok):
     File "C:\Program Files\Python37\lib\contextlib.py", line 112, in __enter__
       return next(self.gen)
     File "C:\Program Files\Python37\lib\site-packages\pymongo\mongo_client.py", line 1101, in _socket_for_reads
       with self._get_socket(server) as sock_info:
     File "C:\Program Files\Python37\lib\contextlib.py", line 112, in __enter__
       return next(self.gen)
     File "C:\Program Files\Python37\lib\site-packages\pymongo\mongo_client.py", line 1058, in _get_socket
       with server.get_socket(self.__all_credentials) as sock_info:
     File "C:\Program Files\Python37\lib\contextlib.py", line 112, in __enter__
       return next(self.gen)
     File "C:\Program Files\Python37\lib\site-packages\pymongo\pool.py", line 1004, in get_socket
       sock_info = self._get_socket_no_auth()
     File "C:\Program Files\Python37\lib\site-packages\pymongo\pool.py", line 1041, in _get_socket_no_auth
       sock_info = self.connect()
     File "C:\Program Files\Python37\lib\site-packages\pymongo\pool.py", line 972, in connect
       _raise_connection_failure(self.address, error)
     File "C:\Program Files\Python37\lib\site-packages\pymongo\pool.py", line 283, in _raise_connection_failure
       raise AutoReconnect(msg)
   pymongo.errors.AutoReconnect: cluster0-shard-00-00-guvid.gcp.mongodb.net:27017: [Errno 11001] getaddrinfo failed
   
   identity: SimpleManager
   facet: 
   operation: rechercherParTitre
   remote host: ::ffff:192.168.43.1 remote port: 46612
-- 05/09/19 21:56:59.151 server/server.py: Network: closed tcp connection
   local address = ::ffff:192.168.43.15:10000
   remote address = ::ffff:192.168.43.1:46612
-- 05/09/19 21:59:47.164 server/server.py: Network: trying to accept tcp connection
   local address = ::ffff:192.168.43.15:10000
   remote address = ::ffff:192.168.43.1:46621
-- 05/09/19 21:59:47.165 server/server.py: Network: accepted tcp connection
   local address = ::ffff:192.168.43.15:10000
   remote address = ::ffff:192.168.43.1:46621
-- 05/09/19 21:59:48.218 server/server.py: Network: closed tcp connection
   local address = ::ffff:192.168.43.15:10000
   remote address = ::ffff:192.168.43.1:46621
-- 05/09/19 21:59:54.925 server/server.py: Network: trying to accept tcp connection
   local address = ::ffff:192.168.43.15:10000
   remote address = ::ffff:192.168.43.1:46624
-- 05/09/19 21:59:54.925 server/server.py: Network: accepted tcp connection
   local address = ::ffff:192.168.43.15:10000
   remote address = ::ffff:192.168.43.1:46624
-! 05/09/19 21:59:54.943 server/server.py: warning: dispatch exception: src\Util.cpp:344: ::Ice::UnknownException:
   unknown exception:
   Traceback (most recent call last):
     File "C:\Program Files\Python37\lib\site-packages\Ice\__init__.py", line 408, in _iceDispatch
       result = method(*args)
     File "server/server.py", line 189, in playPause
       if clientManagementI.clients[port][1] == None:
   KeyError: <IcePy.Current object at 0x0000022666227330>
   
   identity: SimpleManager
   facet: 
   operation: playPause
   remote host: ::ffff:192.168.43.1 remote port: 46624
-- 05/09/19 21:59:54.950 server/server.py: Network: closed tcp connection
   local address = ::ffff:192.168.43.15:10000
   remote address = ::ffff:192.168.43.1:46624
-- 05/09/19 22:01:02.581 server/server.py: Network: trying to accept tcp connection
   local address = ::ffff:192.168.43.15:10000
   remote address = ::ffff:192.168.43.1:46631
-- 05/09/19 22:01:02.582 server/server.py: Network: accepted tcp connection
   local address = ::ffff:192.168.43.15:10000
   remote address = ::ffff:192.168.43.1:46631
-- 05/09/19 22:01:02.855 server/server.py: Network: closed tcp connection
   local address = ::ffff:192.168.43.15:10000
   remote address = ::ffff:192.168.43.1:46631
-- 05/09/19 22:01:07.434 server/server.py: Network: trying to accept tcp connection
   local address = ::ffff:192.168.43.15:10000
   remote address = ::ffff:192.168.43.1:46635
-- 05/09/19 22:01:07.435 server/server.py: Network: accepted tcp connection
   local address = ::ffff:192.168.43.15:10000
   remote address = ::ffff:192.168.43.1:46635
-! 05/09/19 22:01:07.485 server/server.py: warning: dispatch exception: src\Util.cpp:344: ::Ice::UnknownException:
   unknown exception:
   Traceback (most recent call last):
     File "C:\Program Files\Python37\lib\site-packages\Ice\__init__.py", line 408, in _iceDispatch
       result = method(*args)
     File "server/server.py", line 189, in playPause
       if clientManagementI.clients[port][1] is None:
   KeyError: <IcePy.Current object at 0x00000226666435D0>
   
   identity: SimpleManager
   facet: 
   operation: playPause
   remote host: ::ffff:192.168.43.1 remote port: 46635
-- 05/09/19 22:01:07.495 server/server.py: Network: closed tcp connection
   local address = ::ffff:192.168.43.15:10000
   remote address = ::ffff:192.168.43.1:46635
-- 05/09/19 22:03:13.325 server/server.py: Network: stopping to accept tcp connections at :::10000
-- 05/09/19 22:03:20.422 server/server.py: Network: attempting to bind to tcp socket :::10000
-- 05/09/19 22:03:20.429 server/server.py: Network: listening for tcp connections
   local address = :::10000
   local interfaces = 192.168.43.15, ::1, 127.0.0.1
-- 05/09/19 22:03:20.434 server/server.py: Network: published endpoints for object adapter `SimpleManagerAdapter':
   tcp -h 192.168.43.15 -p 10000 -t 60000
-- 05/09/19 22:03:20.434 server/server.py: Network: accepting tcp connections at :::10000
-- 05/09/19 22:03:37.222 server/server.py: Network: trying to accept tcp connection
   local address = ::ffff:192.168.43.15:10000
   remote address = ::ffff:192.168.43.1:46642
-- 05/09/19 22:03:37.222 server/server.py: Network: accepted tcp connection
   local address = ::ffff:192.168.43.15:10000
   remote address = ::ffff:192.168.43.1:46642
-- 05/09/19 22:03:38.185 server/server.py: Network: closed tcp connection
   local address = ::ffff:192.168.43.15:10000
   remote address = ::ffff:192.168.43.1:46642
-- 05/09/19 22:03:44.186 server/server.py: Network: trying to accept tcp connection
   local address = ::ffff:192.168.43.15:10000
   remote address = ::ffff:192.168.43.1:46645
-- 05/09/19 22:03:44.186 server/server.py: Network: accepted tcp connection
   local address = ::ffff:192.168.43.15:10000
   remote address = ::ffff:192.168.43.1:46645
-! 05/09/19 22:03:44.207 server/server.py: warning: dispatch exception: src\Util.cpp:344: ::Ice::UnknownException:
   unknown exception:
   Traceback (most recent call last):
     File "C:\Program Files\Python37\lib\site-packages\Ice\__init__.py", line 408, in _iceDispatch
       result = method(*args)
     File "server/server.py", line 190, in playPause
       if clientManagementI.clients[port][1] is None:
   KeyError: <IcePy.Current object at 0x000001EE34A71E10>
   
   identity: SimpleManager
   facet: 
   operation: playPause
   remote host: ::ffff:192.168.43.1 remote port: 46645
-- 05/09/19 22:03:44.215 server/server.py: Network: closed tcp connection
   local address = ::ffff:192.168.43.15:10000
   remote address = ::ffff:192.168.43.1:46645
-- 05/09/19 22:07:31.265 server/server.py: Network: trying to accept tcp connection
   local address = ::ffff:192.168.43.15:10000
   remote address = ::ffff:192.168.43.15:63954
-- 05/09/19 22:07:31.265 server/server.py: Network: accepted tcp connection
   local address = ::ffff:192.168.43.15:10000
   remote address = ::ffff:192.168.43.15:63954
-! 05/09/19 22:07:42.282 server/server.py: warning: dispatch exception: src\Util.cpp:344: ::Ice::UnknownException:
   unknown exception:
   Traceback (most recent call last):
     File "C:\Program Files\Python37\lib\site-packages\Ice\__init__.py", line 408, in _iceDispatch
       result = method(*args)
     File "server/server.py", line 190, in playPause
       if clientManagementI.clients[port][1] is None:
   KeyError: <IcePy.Current object at 0x000001EE34A34510>
   
   identity: SimpleManager
   facet: 
   operation: playPause
   remote host: ::ffff:192.168.43.15 remote port: 63954
-- 05/09/19 22:07:42.291 server/server.py: Network: closed tcp connection
   local address = ::ffff:192.168.43.15:10000
   remote address = ::ffff:192.168.43.15:63954
-- 05/09/19 22:09:38.508 server/server.py: Network: stopping to accept tcp connections at :::10000
-- 05/09/19 22:12:05.440 server/server.py: Network: attempting to bind to tcp socket :::10000
-- 05/09/19 22:12:05.445 server/server.py: Network: listening for tcp connections
   local address = :::10000
   local interfaces = 192.168.43.15, ::1, 127.0.0.1
-- 05/09/19 22:12:05.448 server/server.py: Network: published endpoints for object adapter `SimpleManagerAdapter':
   tcp -h 192.168.43.15 -p 10000 -t 60000
-- 05/09/19 22:12:05.449 server/server.py: Network: accepting tcp connections at :::10000
-- 05/09/19 22:12:06.584 server/server.py: Network: trying to accept tcp connection
   local address = ::ffff:192.168.43.15:10000
   remote address = ::ffff:192.168.43.15:64099
-- 05/09/19 22:12:06.584 server/server.py: Network: accepted tcp connection
   local address = ::ffff:192.168.43.15:10000
   remote address = ::ffff:192.168.43.15:64099
-! 05/09/19 22:12:33.500 server/server.py: warning: dispatch exception: src\Util.cpp:344: ::Ice::UnknownException:
   unknown exception:
   Traceback (most recent call last):
     File "C:\Program Files\Python37\lib\site-packages\Ice\__init__.py", line 408, in _iceDispatch
       result = method(*args)
     File "server/server.py", line 46, in unsubscribe
       print("Client with port " + port + " unsubscribed")
   TypeError: can only concatenate str (not "int") to str
   
   identity: SimpleClientManager
   facet: 
   operation: unsubscribe
   remote host: ::ffff:192.168.43.15 remote port: 64099
-- 05/09/19 22:12:33.503 server/server.py: Network: closed tcp connection
   local address = ::ffff:192.168.43.15:10000
   remote address = ::ffff:192.168.43.15:64099
-- 05/09/19 22:17:51.117 server/server.py: Network: trying to accept tcp connection
   local address = ::ffff:192.168.43.15:10000
   remote address = ::ffff:192.168.43.1:46673
-- 05/09/19 22:17:51.118 server/server.py: Network: accepted tcp connection
   local address = ::ffff:192.168.43.15:10000
   remote address = ::ffff:192.168.43.1:46673
-- 05/09/19 22:17:51.361 server/server.py: Network: closed tcp connection
   local address = ::ffff:192.168.43.15:10000
   remote address = ::ffff:192.168.43.1:46673
-- 05/09/19 22:23:55.134 server/server.py: Network: trying to accept tcp connection
   local address = ::ffff:192.168.43.15:10000
   remote address = ::ffff:192.168.43.1:46684
-- 05/09/19 22:23:55.135 server/server.py: Network: accepted tcp connection
   local address = ::ffff:192.168.43.15:10000
   remote address = ::ffff:192.168.43.1:46684
-- 05/09/19 22:23:55.399 server/server.py: Network: closed tcp connection
   local address = ::ffff:192.168.43.15:10000
   remote address = ::ffff:192.168.43.1:46684
-- 05/09/19 22:24:01.917 server/server.py: Network: trying to accept tcp connection
   local address = ::ffff:192.168.43.15:10000
   remote address = ::ffff:192.168.43.1:46687
-- 05/09/19 22:24:01.917 server/server.py: Network: accepted tcp connection
   local address = ::ffff:192.168.43.15:10000
   remote address = ::ffff:192.168.43.1:46687
-- 05/09/19 22:24:01.940 server/server.py: Network: closed tcp connection
   local address = ::ffff:192.168.43.15:10000
   remote address = ::ffff:192.168.43.1:46687
-- 05/09/19 22:24:07.328 server/server.py: Network: trying to accept tcp connection
   local address = ::ffff:192.168.43.15:10000
   remote address = ::ffff:192.168.43.1:46689
-- 05/09/19 22:24:07.328 server/server.py: Network: accepted tcp connection
   local address = ::ffff:192.168.43.15:10000
   remote address = ::ffff:192.168.43.1:46689
-- 05/09/19 22:24:07.349 server/server.py: Network: closed tcp connection
   local address = ::ffff:192.168.43.15:10000
   remote address = ::ffff:192.168.43.1:46689
-- 05/09/19 22:24:16.217 server/server.py: Network: trying to accept tcp connection
   local address = ::ffff:192.168.43.15:10000
   remote address = ::ffff:192.168.43.1:46690
-- 05/09/19 22:24:16.217 server/server.py: Network: accepted tcp connection
   local address = ::ffff:192.168.43.15:10000
   remote address = ::ffff:192.168.43.1:46690
-- 05/09/19 22:24:16.238 server/server.py: Network: closed tcp connection
   local address = ::ffff:192.168.43.15:10000
   remote address = ::ffff:192.168.43.1:46690
-- 05/09/19 22:24:23.742 server/server.py: Network: trying to accept tcp connection
   local address = ::ffff:192.168.43.15:10000
   remote address = ::ffff:192.168.43.1:46691
-- 05/09/19 22:24:23.743 server/server.py: Network: accepted tcp connection
   local address = ::ffff:192.168.43.15:10000
   remote address = ::ffff:192.168.43.1:46691
-- 05/09/19 22:24:23.764 server/server.py: Network: closed tcp connection
   local address = ::ffff:192.168.43.15:10000
   remote address = ::ffff:192.168.43.1:46691
-- 05/09/19 22:24:34.569 server/server.py: Network: trying to accept tcp connection
   local address = ::ffff:192.168.43.15:10000
   remote address = ::ffff:192.168.43.1:46692
-- 05/09/19 22:24:34.569 server/server.py: Network: accepted tcp connection
   local address = ::ffff:192.168.43.15:10000
   remote address = ::ffff:192.168.43.1:46692
-- 05/09/19 22:24:34.592 server/server.py: Network: closed tcp connection
   local address = ::ffff:192.168.43.15:10000
   remote address = ::ffff:192.168.43.1:46692
-- 05/09/19 22:25:06.378 server/server.py: Network: trying to accept tcp connection
   local address = ::ffff:192.168.43.15:10000
   remote address = ::ffff:192.168.43.1:46696
-- 05/09/19 22:25:06.379 server/server.py: Network: accepted tcp connection
   local address = ::ffff:192.168.43.15:10000
   remote address = ::ffff:192.168.43.1:46696
-- 05/09/19 22:25:06.399 server/server.py: Network: closed tcp connection
   local address = ::ffff:192.168.43.15:10000
   remote address = ::ffff:192.168.43.1:46696
-- 05/09/19 22:25:54.342 server/server.py: Network: trying to accept tcp connection
   local address = ::ffff:192.168.43.15:10000
   remote address = ::ffff:192.168.43.1:46697
-- 05/09/19 22:25:54.342 server/server.py: Network: accepted tcp connection
   local address = ::ffff:192.168.43.15:10000
   remote address = ::ffff:192.168.43.1:46697
-- 05/09/19 22:25:54.363 server/server.py: Network: closed tcp connection
   local address = ::ffff:192.168.43.15:10000
   remote address = ::ffff:192.168.43.1:46697
-- 05/09/19 22:26:54.185 server/server.py: Network: trying to accept tcp connection
   local address = ::ffff:192.168.43.15:10000
   remote address = ::ffff:192.168.43.1:46704
-- 05/09/19 22:26:54.186 server/server.py: Network: accepted tcp connection
   local address = ::ffff:192.168.43.15:10000
   remote address = ::ffff:192.168.43.1:46704
-- 05/09/19 22:26:54.207 server/server.py: Network: closed tcp connection
   local address = ::ffff:192.168.43.15:10000
   remote address = ::ffff:192.168.43.1:46704
-- 05/09/19 22:43:08.285 server/server.py: Network: trying to accept tcp connection
   local address = ::ffff:192.168.43.15:10000
   remote address = ::ffff:192.168.43.1:46727
-- 05/09/19 22:43:08.286 server/server.py: Network: accepted tcp connection
   local address = ::ffff:192.168.43.15:10000
   remote address = ::ffff:192.168.43.1:46727
-! 05/09/19 22:43:08.547 server/server.py: warning: dispatch exception: src\Util.cpp:344: ::Ice::UnknownException:
   unknown exception:
   Traceback (most recent call last):
     File "C:\Program Files\Python37\lib\site-packages\Ice\__init__.py", line 408, in _iceDispatch
       result = method(*args)
     File "server/server.py", line 162, in jouerMorceaux
       if clientManagementI.clients[port][1] is None:
   KeyError: 0
   
   identity: SimpleManager
   facet: 
   operation: jouerMorceaux
   remote host: ::ffff:192.168.43.1 remote port: 46727
-- 05/09/19 22:43:08.562 server/server.py: Network: closed tcp connection
   local address = ::ffff:192.168.43.15:10000
   remote address = ::ffff:192.168.43.1:46727
-- 05/09/19 22:45:10.938 server/server.py: Network: trying to accept tcp connection
   local address = ::ffff:192.168.43.15:10000
   remote address = ::ffff:192.168.43.1:46734
-- 05/09/19 22:45:10.939 server/server.py: Network: accepted tcp connection
   local address = ::ffff:192.168.43.15:10000
   remote address = ::ffff:192.168.43.1:46734
-- 05/09/19 22:45:11.230 server/server.py: Network: closed tcp connection
   local address = ::ffff:192.168.43.15:10000
   remote address = ::ffff:192.168.43.1:46734
-- 05/09/19 22:49:23.495 server/server.py: Network: trying to accept tcp connection
   local address = ::ffff:192.168.43.15:10000
   remote address = ::ffff:192.168.43.1:46744
-- 05/09/19 22:49:23.495 server/server.py: Network: accepted tcp connection
   local address = ::ffff:192.168.43.15:10000
   remote address = ::ffff:192.168.43.1:46744
-- 05/09/19 22:49:23.755 server/server.py: Network: closed tcp connection
   local address = ::ffff:192.168.43.15:10000
   remote address = ::ffff:192.168.43.1:46744
-- 05/09/19 22:55:46.868 server/server.py: Network: trying to accept tcp connection
   local address = ::ffff:192.168.43.15:10000
   remote address = ::ffff:192.168.43.1:46757
-- 05/09/19 22:55:46.869 server/server.py: Network: accepted tcp connection
   local address = ::ffff:192.168.43.15:10000
   remote address = ::ffff:192.168.43.1:46757
-- 05/09/19 22:55:47.112 server/server.py: Network: closed tcp connection
   local address = ::ffff:192.168.43.15:10000
   remote address = ::ffff:192.168.43.1:46757
-- 05/09/19 22:55:56.897 server/server.py: Network: trying to accept tcp connection
   local address = ::ffff:192.168.43.15:10000
   remote address = ::ffff:192.168.43.1:46761
-- 05/09/19 22:55:56.897 server/server.py: Network: accepted tcp connection
   local address = ::ffff:192.168.43.15:10000
   remote address = ::ffff:192.168.43.1:46761
-- 05/09/19 22:55:57.109 server/server.py: Network: closed tcp connection
   local address = ::ffff:192.168.43.15:10000
   remote address = ::ffff:192.168.43.1:46761
-- 05/09/19 23:29:03.471 server/server.py: Network: trying to accept tcp connection
   local address = ::ffff:192.168.43.15:10000
   remote address = ::ffff:192.168.43.1:46807
-- 05/09/19 23:29:03.473 server/server.py: Network: accepted tcp connection
   local address = ::ffff:192.168.43.15:10000
   remote address = ::ffff:192.168.43.1:46807
-- 05/09/19 23:29:03.812 server/server.py: Network: closed tcp connection
   local address = ::ffff:192.168.43.15:10000
   remote address = ::ffff:192.168.43.1:46807
-- 05/10/19 00:03:18.209 server/server.py: Network: trying to accept tcp connection
   local address = ::ffff:192.168.43.15:10000
   remote address = ::ffff:192.168.43.1:46857
-- 05/10/19 00:03:18.210 server/server.py: Network: accepted tcp connection
   local address = ::ffff:192.168.43.15:10000
   remote address = ::ffff:192.168.43.1:46857
-- 05/10/19 00:03:18.501 server/server.py: Network: closed tcp connection
   local address = ::ffff:192.168.43.15:10000
   remote address = ::ffff:192.168.43.1:46857
-- 05/10/19 00:31:31.702 server/server.py: Network: trying to accept tcp connection
   local address = ::ffff:192.168.43.15:10000
   remote address = ::ffff:192.168.43.1:46917
-- 05/10/19 00:31:31.702 server/server.py: Network: accepted tcp connection
   local address = ::ffff:192.168.43.15:10000
   remote address = ::ffff:192.168.43.1:46917
-- 05/10/19 00:31:31.975 server/server.py: Network: closed tcp connection
   local address = ::ffff:192.168.43.15:10000
   remote address = ::ffff:192.168.43.1:46917
-- 05/10/19 00:33:37.084 server/server.py: Network: trying to accept tcp connection
   local address = ::ffff:192.168.43.15:10000
   remote address = ::ffff:192.168.43.1:46929
-- 05/10/19 00:33:37.085 server/server.py: Network: accepted tcp connection
   local address = ::ffff:192.168.43.15:10000
   remote address = ::ffff:192.168.43.1:46929
-- 05/10/19 00:33:37.345 server/server.py: Network: closed tcp connection
   local address = ::ffff:192.168.43.15:10000
   remote address = ::ffff:192.168.43.1:46929
